<mujoco>
	<option>
		<flag sensornoise="enable" />
	</option>
	<worldbody>
        <light diffuse=".5 .5 .5" pos="0 0 3" dir="0 0 -1"/>
		<geom type="plane" size="1 1 0.1" rgba=".5 1 0 1"/>
		<body name = "chassis" pos="0 0 1.5" euler='0 90 0'>
			<!-- joint type="free"/-->
			<joint name = "base" type="slide" axis="0 0 -1"/>
			<geom type="box" size=".05 .2 .5" rgba=".9 .9 0 1" mass="10"/>
			<body pos="-0.5 0.3 0" euler="0 90 0">
				<joint name="j2" type="hinge" axis = "0 -1 0" pos="0 0 0.5" damping="0.01" />
				<geom type="cylinder" size="0.05 0.5" rgba="1 .9 0 1" mass="0.1"/>
			</body>


			<!--
			<body name="left-tire" pos="0 0.3 -0.5" euler='90 0 0'>
				<joint name = "left-wheel" type="hinge" axis="0 0 -1"/>
				<geom type="cylinder" size=".2 0.05" rgba="0 .9 0 1"/>
			</body>
			<body name="right-tire" pos="0 -0.3 -0.5" euler='90 0 0'>
				<joint name = "right-wheel" type="hinge" axis="0 0 -1"/>
				<geom type="cylinder" size=".2 0.05" rgba="0 .9 0 1"/>
			</body>
			-->
		</body>
	</worldbody>

	<actuator>
		<!--
		<velocity name="base-velocity-servo" joint="base" kv="100"/>
		-->
		<motor joint="base" name="torque" gear="1" ctrllimited="true" ctrlrange="-100 100" />
		<!--
		<velocity name="left-velocity-servo" joint="left-wheel" kv="100"/>
		<velocity name="right-velocity-servo" joint="right-wheel" kv="100"/>
		-->
	</actuator>

<!-- ======= Ground ======= 
			<joint name="j1" type="hinge" axis = "0 -1 0" pos="0 0 0.5"/>
			<geom type="box" size="0.05 0.5" rgba="1 .9 0 1" mass="1"/>
			<body pos="0 0 2" euler="0 180 0">
				<joint name="j2" type="hinge" axis = "0 -1 0" pos="0 0 0.5"/>
				<geom type="cylinder" size="0.05 0.5" rgba="1 .9 0 1" mass="1"/>
			</body>
		</body>
		-->
<!-- ======= Ground ======= 
	<actuator>
		<motor joint="pin" name="torque" gear="1" ctrllimited="true" ctrlrange="-100 100" />
		<position name="position_servo" joint="pin" kp="0" />
		<velocity name="velocity_servo" joint="pin" kv="0" />
	</actuator>
	<sensor>
		<jointpos joint="pin" noise="0.2"/>
		<jointvel joint="pin" noise="1" />
	</sensor>
		-->
</mujoco>
