<mujoco model="panda">
  <compiler angle="radian" meshdir="../meshes/visual/"/>
  <asset>
    <mesh name="link0" file="link0.stl"/>
    <mesh name="link1" file="link1.stl"/>
    <mesh name="link2" file="link2.stl"/>
    <mesh name="link3" file="link3.stl"/>
    <mesh name="link4" file="link4.stl"/>
    <mesh name="link5" file="link5.stl"/>
    <mesh name="link6" file="link6.stl"/>
    <mesh name="link7" file="link7.stl"/>
  </asset>
  <worldbody>
    <geom type="mesh" contype="0" conaffinity="0" group="1" density="0" mesh="link0"/>
    <geom type="mesh" mesh="link0"/>
    <body name="panda_link1" pos="0 0 0.333">
      <inertial pos="0.003875 0.002081 -0.175" quat="0.711549 0.00634377 -0.0131124 0.702485" mass="4.97068" diaginertia="0.707137 0.703435 0.00852456"/>
      <joint name="panda_joint1" pos="0 0 0" axis="0 0 1" limited="true" range="-2.8973 2.8973" damping="10" frictionloss="5"/>
      <geom type="mesh" contype="0" conaffinity="0" group="1" density="0" mesh="link1"/>
      <geom type="mesh" mesh="link1"/>
      <body name="panda_link2" quat="0.707107 -0.707107 0 0">
        <inertial pos="-0.003141 -0.02872 0.003495" quat="-0.168175 0.828366 -0.122878 0.520027" mass="0.646926" diaginertia="0.0310326 0.0283001 0.00273425"/>
        <joint name="panda_joint2" pos="0 0 0" axis="0 0 1" limited="true" range="-1.7628 1.7628" damping="5" frictionloss="2"/>
        <geom type="mesh" contype="0" conaffinity="0" group="1" density="0" mesh="link2"/>
        <geom type="mesh" mesh="link2"/>
        <body name="panda_link3" pos="0 -0.316 0" quat="0.707107 0.707107 0 0">
          <inertial pos="0.027518 0.039252 -0.066502" quat="0.662769 -0.00678331 0.252053 0.705096" mass="3.2286" diaginertia="0.0415014 0.0414793 0.00124635"/>
          <joint name="panda_joint3" pos="0 0 0" axis="0 0 1" limited="true" range="-2.8973 2.8973" damping="5" frictionloss="2"/>
          <geom type="mesh" contype="0" conaffinity="0" group="1" density="0" mesh="link3"/>
          <geom type="mesh" mesh="link3"/>
          <body name="panda_link4" pos="0.0825 0 0" quat="0.707107 0.707107 0 0">
            <inertial pos="-0.05317 0.104419 0.027454" quat="0.65058 0.529822 -0.0962034 0.535518" mass="3.5879" diaginertia="0.0349596 0.0281483 0.0106201"/>
            <joint name="panda_joint4" pos="0 0 0" axis="0 0 1" limited="true" range="-3.0718 -0.0698" damping="1" frictionloss="0.5"/>
            <geom type="mesh" contype="0" conaffinity="0" group="1" density="0" mesh="link4"/>
            <geom type="mesh" mesh="link4"/>
            <body name="panda_link5" pos="-0.0825 0.384 0" quat="0.707107 -0.707107 0 0">
              <inertial pos="-0.011953 0.041065 -0.038437" quat="0.987313 -0.0121954 0.0719187 -0.141037" mass="1.22595" diaginertia="0.0367625 0.0288531 0.00803437"/>
              <joint name="panda_joint5" pos="0 0 0" axis="0 0 1" limited="true" range="-2.8973 2.8973" damping="2" frictionloss="1"/>
              <geom type="mesh" contype="0" conaffinity="0" group="1" density="0" mesh="link5"/>
              <geom type="mesh" mesh="link5"/>
              <body name="panda_link6" quat="0.707107 0.707107 0 0">
                <inertial pos="0.060149 -0.014117 -0.010517" quat="0.101075 0.59332 0.0287227 0.798079" mass="1.66656" diaginertia="0.00584276 0.00431037 0.00159787"/>
                <joint name="panda_joint6" pos="0 0 0" axis="0 0 1" limited="true" range="-0.0175 3.7525" damping="1" frictionloss="0.5"/>
                <geom type="mesh" contype="0" conaffinity="0" group="1" density="0" mesh="link6"/>
                <geom type="mesh" mesh="link6"/>
                <body name="panda_link7" pos="0.088 0 0" quat="0.707107 0.707107 0 0">
                  <inertial pos="0.010517 -0.004252 0.061597" quat="0.992939 -0.0762041 0.0733595 -0.0537067" mass="0.735522" diaginertia="0.0127345 0.0101055 0.00451803"/>
                  <joint name="panda_joint7" pos="0 0 0" axis="0 0 1" limited="true" range="-2.8973 2.8973" damping="1" frictionloss="0.5"/>
                  <geom type="mesh" contype="0" conaffinity="0" group="1" density="0" mesh="link7"/>
                  <geom type="mesh" mesh="link7"/>
                </body>
              </body>
            </body>
          </body>
        </body>
      </body>
    </body>
  </worldbody>
  <!-- Additional configuration -->
  <include file="panda_arm_config_mjcf.xml"></include>
</mujoco>
